#VRML_SIM R2019a utf8
WorldInfo {
}
Viewpoint {
  orientation -0.8054902181942718 0.5113268344842512 0.29955029081885326 1.1465566466234607
  position 0.7158720897705911 1.9216152208964636 0.702953266012586
}
TexturedBackground {
}
TexturedBackgroundLight {
}
Floor {
}
Robot {
  translation 0 0.15 0
  children [
    Shape {
      appearance PBRAppearance {
        baseColor 0.5411764705882353 0.8862745098039215 0.20392156862745098
      }
      geometry Box {
        size 0.1 0.3 0.1
      }
    }
    HingeJoint {
      jointParameters HingeJointParameters {
        axis 0 1 0
        anchor 0 0.15 0
      }
      device [
        RotationalMotor {
          name "servo_motor"
          maxVelocity 13.1
          maxTorque 0.2157
        }
      ]
      endPoint Solid {
        translation 0 0.2 0
        children [
          Shape {
            appearance PBRAppearance {
              baseColor 0.8 0 0
            }
            geometry DEF G_RED_BOX Box {
              size 0.1 0.1 0.1
            }
          }
          HingeJoint {
            jointParameters HingeJointParameters {
              anchor 0 0.05 0
            }
            endPoint Solid {
              translation 0 0.2500000000000002 8.326672684688674e-17
              rotation 1 0 0 0
              children [
                Shape {
                  appearance PBRAppearance {
                    baseColor 0.9294117647058824 0.8313725490196079 0
                  }
                  geometry DEF G_YELLOWBOX Box {
                    size 0.05 0.4 0.1
                  }
                }
                HingeJoint {
                  jointParameters HingeJointParameters {
                    anchor 0 0.3 0
                  }
                  endPoint Solid {
                    translation 0 0.3 0
                    children [
                      Shape {
                        appearance PBRAppearance {
                        }
                        geometry Box {
                          size 0.05 0.2 0.1
                        }
                      }
                    ]
                  }
                }
              ]
              boundingObject USE G_YELLOWBOX
              physics Physics {
              }
            }
          }
        ]
        boundingObject USE G_RED_BOX
        physics Physics {
        }
      }
    }
  ]
  controller "Robot2"
}
