#VRML_SIM R2019a utf8
WorldInfo {
}
Viewpoint {
  orientation -0.9752570449779927 -0.20472054164283401 0.08344576712007697 0.3493145401271494
  position -0.0011007539511393993 0.5362682924288045 0.9399227506507483
}
TexturedBackground {
}
TexturedBackgroundLight {
}
Floor {
}
Robot {
  translation 0 0.15 0
  children [
    Shape {
      appearance PBRAppearance {
        baseColor 0.5411764705882353 0.8862745098039215 0.20392156862745098
      }
      geometry Box {
        size 0.1 0.3 0.1
      }
    }
    HingeJoint {
      jointParameters HingeJointParameters {
        axis 0 1 0
        anchor 0 0.15 0
      }
      device [
        RotationalMotor {
          name "servo_motor"
          maxVelocity 0.026
          maxTorque 0.2157
        }
      ]
      endPoint Solid {
        translation 0 0.2 0
        children [
          Shape {
            appearance PBRAppearance {
              baseColor 0.8 0 0
            }
            geometry DEF G_RED_BOX Box {
              size 0.1 0.1 0.1
            }
          }
        ]
        boundingObject USE G_RED_BOX
        physics Physics {
        }
      }
    }
  ]
}
